<?xml version="1.0" encoding="UTF-8"?>
<!-- Generated by org.testng.reporters.JUnitReportReporter -->
<testsuite hostname="liMac.local" failures="1" tests="2" name="org.jpwh.test.simple.ModelOperations" time="0.002" errors="0" timestamp="31 Aug 2020 01:03:57 GMT">
  <testcase classname="org.jpwh.test.simple.ModelOperations" name="linkBidAndItem" time="0.001"/>
  <testcase classname="org.jpwh.test.simple.ModelOperations" name="validateItem" time="0.001">
    <failure message="Unable to instantiate Configuration." type="javax.validation.ValidationException">
      <![CDATA[javax.validation.ValidationException: Unable to instantiate Configuration.
	at javax.validation.Validation$GenericBootstrapImpl.configure(Validation.java:279)
	at javax.validation.Validation.buildDefaultValidatorFactory(Validation.java:110)
	at org.jpwh.test.simple.ModelOperations.validateItem(ModelOperations.java:42)
	at java.base/jdk.internal.reflect.NativeMethodAccessorImpl.invoke0(Native Method)
	at java.base/jdk.internal.reflect.NativeMethodAccessorImpl.invoke(NativeMethodAccessorImpl.java:62)
	at java.base/jdk.internal.reflect.DelegatingMethodAccessorImpl.invoke(DelegatingMethodAccessorImpl.java:43)
	at java.base/java.lang.reflect.Method.invoke(Method.java:564)
	at org.testng.internal.MethodInvocationHelper.invokeMethod(MethodInvocationHelper.java:84)
	at org.testng.internal.Invoker.invokeMethod(Invoker.java:714)
	at org.testng.internal.Invoker.invokeTestMethod(Invoker.java:901)
	at org.testng.internal.Invoker.invokeTestMethods(Invoker.java:1231)
	at org.testng.internal.TestMethodWorker.invokeTestMethods(TestMethodWorker.java:127)
	at org.testng.internal.TestMethodWorker.run(TestMethodWorker.java:111)
	at org.testng.TestRunner.privateRun(TestRunner.java:767)
	at org.testng.TestRunner.run(TestRunner.java:617)
	at org.testng.SuiteRunner.runTest(SuiteRunner.java:334)
	at org.testng.SuiteRunner.runSequentially(SuiteRunner.java:329)
	at org.testng.SuiteRunner.privateRun(SuiteRunner.java:291)
	at org.testng.SuiteRunner.run(SuiteRunner.java:240)
	at org.testng.SuiteRunnerWorker.runSuite(SuiteRunnerWorker.java:52)
	at org.testng.SuiteRunnerWorker.run(SuiteRunnerWorker.java:86)
	at org.testng.TestNG.runSuitesSequentially(TestNG.java:1224)
	at org.testng.TestNG.runSuitesLocally(TestNG.java:1149)
	at org.testng.TestNG.run(TestNG.java:1057)
	at org.apache.maven.surefire.testng.TestNGExecutor.run(TestNGExecutor.java:122)
	at org.apache.maven.surefire.testng.TestNGXmlTestSuite.execute(TestNGXmlTestSuite.java:92)
	at org.apache.maven.surefire.testng.TestNGProvider.invoke(TestNGProvider.java:101)
	at java.base/jdk.internal.reflect.NativeMethodAccessorImpl.invoke0(Native Method)
	at java.base/jdk.internal.reflect.NativeMethodAccessorImpl.invoke(NativeMethodAccessorImpl.java:62)
	at java.base/jdk.internal.reflect.DelegatingMethodAccessorImpl.invoke(DelegatingMethodAccessorImpl.java:43)
	at java.base/java.lang.reflect.Method.invoke(Method.java:564)
	at org.apache.maven.surefire.util.ReflectionUtils.invokeMethodWithArray(ReflectionUtils.java:164)
	at org.apache.maven.surefire.booter.ProviderFactory$ProviderProxy.invoke(ProviderFactory.java:110)
	at org.apache.maven.surefire.booter.SurefireStarter.invokeProvider(SurefireStarter.java:172)
	at org.apache.maven.surefire.booter.SurefireStarter.runSuitesInProcessWhenForked(SurefireStarter.java:104)
	at org.apache.maven.surefire.booter.ForkedBooter.main(ForkedBooter.java:70)
Caused by: java.lang.ArrayIndexOutOfBoundsException: 1
	at org.hibernate.validator.internal.util.Version.getJavaRelease(Version.java:36)
	at org.hibernate.validator.internal.engine.ConfigurationImpl.<init>(ConfigurationImpl.java:119)
	at org.hibernate.validator.internal.engine.ConfigurationImpl.<init>(ConfigurationImpl.java:95)
	at org.hibernate.validator.HibernateValidator.createGenericConfiguration(HibernateValidator.java:31)
	at javax.validation.Validation$GenericBootstrapImpl.configure(Validation.java:276)
	... 35 more
]]>
    </failure>
  </testcase> <!-- validateItem -->
</testsuite> <!-- org.jpwh.test.simple.ModelOperations -->
